Workbook

Sheet Dashboard
B1: Financial Performance Dashboard
B2: Reporting period: Sep 2013 – Dec 2014 (2013 covers Sep–Dec only) · 695 orders · 5 segments, 5 countries, 6 products · Source: Financials sheet · Currency symbol shown as $ (unit not stated in source)
B4: PERIOD (YEAR) | H4: SEGMENT | N4: COUNTRY | T4: PRODUCT
B5: All | H5: All | N5: All | T5: All
B6: ="Showing "&TEXT(Calc!B15,"#,##0")&" orders · Pick values in the four white boxes above (set all to All to reset). Segment, Country and Product charts ignore their own filter so comparisons stay visible."
B8: 1 · EXECUTIVE OVERVIEW
B9: NET SALES | F9: PROFIT | J9: PROFIT MARGIN | N9: DISCOUNT RATE | R9: UNITS SOLD | V9: LOSS-MAKING ORDERS
B10: =Calc!B11 | F10: =Calc!B13 | J10: =Calc!B18 | N10: =Calc!B19 | R10: =Calc!B14 | V10: =Calc!B17
B12: ="Gross sales "&TEXT(Calc!B9/1000000,"$0.0")&"M less discounts" | F12: ="COGS = "&TEXT(Calc!B21,"0%")&" of net sales" | J12: ="Profit ÷ net sales" | N12: =TEXT(Calc!B10/1000000,"$0.0")&"M discounts ÷ gross sales" | R12: =TEXT(Calc!B15,"#,##0")&" orders" | V12: =TEXT(Calc!B16,"#,##0")&" orders ("&TEXT(Calc!B16/MAX(Calc!B15,1),"0%")&" of all)"
B13: =Calc!G24 | F13: =Calc!G25 | J13: =Calc!G30 | N13: =Calc!G31 | R13: =Calc!G28 | V13: =Calc!G29
B14: LFL = like-for-like: Sep–Dec 2014 vs Sep–Dec 2013, the only months present in both years (respects Segment, Country, Product filters). Green = favourable, red = unfavourable for that KPI (e.g. a higher discount rate or a larger loss is red). Cards show the selected Period.
B16: 2 · PERFORMANCE ANALYSIS
B17: =Calc!B122 | N17: =Calc!B123
B38: =Calc!B124 | N38: =Calc!B125
B59: 3 · DIAGNOSTICS
B60: =Calc!B126 | N60: Product performance (ignores Product filter)
B61: Segment | E61: No discount | G61: Low | I61: Medium | K61: High | M61: All | N61: Product | Q61: Net sales | S61: Profit | U61: Margin | W61: Profit share
B62: =Calc!A94 | E62: =Calc!B94 | G62: =Calc!C94 | I62: =Calc!D94 | K62: =Calc!E94 | M62: =Calc!F94 | N62: =Calc!A66 | Q62: =Calc!B66 | S62: =Calc!C66 | U62: =Calc!D66 | W62: =Calc!G66
B63: =Calc!A95 | E63: =Calc!B95 | G63: =Calc!C95 | I63: =Calc!D95 | K63: =Calc!E95 | M63: =Calc!F95 | N63: =Calc!A67 | Q63: =Calc!B67 | S63: =Calc!C67 | U63: =Calc!D67 | W63: =Calc!G67
B64: =Calc!A96 | E64: =Calc!B96 | G64: =Calc!C96 | I64: =Calc!D96 | K64: =Calc!E96 | M64: =Calc!F96 | N64: =Calc!A68 | Q64: =Calc!B68 | S64: =Calc!C68 | U64: =Calc!D68 | W64: =Calc!G68
B65: =Calc!A97 | E65: =Calc!B97 | G65: =Calc!C97 | I65: =Calc!D97 | K65: =Calc!E97 | M65: =Calc!F97 | N65: =Calc!A69 | Q65: =Calc!B69 | S65: =Calc!C69 | U65: =Calc!D69 | W65: =Calc!G69
B66: =Calc!A98 | E66: =Calc!B98 | G66: =Calc!C98 | I66: =Calc!D98 | K66: =Calc!E98 | M66: =Calc!F98 | N66: =Calc!A70 | Q66: =Calc!B70 | S66: =Calc!C70 | U66: =Calc!D70 | W66: =Calc!G70
B67: =Calc!A99 | E67: =Calc!B99 | G67: =Calc!C99 | I67: =Calc!D99 | K67: =Calc!E99 | M67: =Calc!F99 | N67: =Calc!A71 | Q67: =Calc!B71 | S67: =Calc!C71 | U67: =Calc!D71 | W67: =Calc!G71
B68: Margin = profit ÷ net sales. Bands are the dataset’s own labels; mix differs by segment, so read down each row, not across segments.
B70: Enterprise unit economics — why discounts erase profit | N70: Country performance (ignores Country filter)
B71: Avg list price per unit | J71: =Calc!B111 | N71: Country | Q71: Net sales | S71: Profit | U71: Margin | W71: Profit share
B72: Avg COGS per unit | J72: =Calc!B112 | N72: =Calc!A76 | Q72: =Calc!B76 | S72: =Calc!C76 | U72: =Calc!D76 | W72: =Calc!G76
B73: Margin before discounts (break-even discount) | J73: =Calc!B113 | N73: =Calc!A77 | Q73: =Calc!B77 | S73: =Calc!C77 | U73: =Calc!D77 | W73: =Calc!G77
B74: Average discount rate actually given | J74: =Calc!B114 | N74: =Calc!A78 | Q74: =Calc!B78 | S74: =Calc!C78 | U74: =Calc!D78 | W74: =Calc!G78
B75: Loss-making orders / total orders | J75: =Calc!B116&" / "&Calc!B115 | N75: =Calc!A79 | Q75: =Calc!B79 | S75: =Calc!C79 | U75: =Calc!D79 | W75: =Calc!G79
B76: Loss orders in Medium/High discount bands | J76: =Calc!B117 | N76: =Calc!A80 | Q76: =Calc!B80 | S76: =Calc!C80 | U76: =Calc!D80 | W76: =Calc!G80
B77: Fact: average Enterprise COGS is close to its list price, leaving a thin pre-discount margin. Interpretation (to verify): discounts above that margin make an order loss-making. | N77: ="Lowest-margin country: "&INDEX(Calc!A76:A80,MATCH(MIN(Calc!D76:D80),Calc!D76:D80,0))&" ("&TEXT(MIN(Calc!D76:D80),"0.0%")&"). Margin gaps between products and countries are narrow compared with the gaps between segments."
B81: 4 · INSIGHTS AND ACTIONS (written from the full dataset, Sep 2013 – Dec 2014; do not change with the filters)
B82: KEY FINDINGS (facts) | J82: RISKS AND ANOMALIES | R82: RECOMMENDED ACTIONS
B83: • Government delivers 45% of net sales but 67% of profit; Small Business adds 25%. Two segments carry the business. • Enterprise is the only loss-making segment: $0.61M net loss on $18.76M sales (-3.3% margin). 58 of 95 Enterprise orders lose money. • Growth is not profit: Enterprise like-for-like sales rose +40% (Sep–Dec) while its net loss widened from $0.19M to $0.22M. • Company like-for-like (Sep–Dec): sales +36%, profit +40%, margin 14.7% → 15.1%, discount rate 7.5% → 6.4%. • Margin falls as discount band rises (21.9% none → 9.1% High), and the same ordering holds inside every segment (see heatmap). This is an association, not proof of cause. | J83: • Enterprise average list price is $125/unit against COGS of $120/unit: a 4% margin before discount. All 58 loss orders carry discounts of 5–15%; profitable Enterprise orders carry 0–3%. • Channel Partners shows a 73% margin on only 1.5% of sales. Unusually high: check its COGS before treating it as an opportunity. • Data checks: COGS does not equal units × Manufacturing_Price, and Sale_Price varies by segment (Government product prices of $7, $20 and $350). COGS and Sales are used as reported. • Revenue and profit are concentrated: a drop in Government would hit profit hard. • The Date column has day and month swapped; Year and Month_Number are used instead. 2013 has only 4 months, so no full-year comparison is possible. | R83: 1. Review Enterprise pricing and discount policy: set an approval threshold near the break-even discount (about 4%) and re-test the segment’s list price against COGS. 2. Re-check the 58 loss-making Enterprise orders: who approved the discounts, and were they tied to volume or strategic accounts? 3. Validate Channel Partners costs with finance; if margin is real, test whether the segment can scale. 4. Reconcile COGS with Manufacturing_Price and the Government price list; fix the Date field at source. 5. Supply targets/budget and full-year 2013 data so performance can be judged against plan, not just against a partial prior period. Questions to investigate: Why does the United States have the lowest margin? (Hypothesis: heavier Enterprise and Small Business mix. Not proven.)

Sheet Detail1
A1: Details for Sum of Profit - Product : Paseo , Segment: Channel Partners
A3: Segment | B3: Country | C3: Product | D3: Discount_Band | E3: Units_Sold | F3: Manufacturing_Price | G3: Sale_Price | H3: Gross_Sales | I3: Discounts | J3: Sales | K3: COGS | L3: Profit | M3: Date | N3: Month_Number | O3: Month_Name | P3: Year | Q3: is_fractional_units | R3: Profit_Margin | S3: Cogs_Ratio | T3: Discount_Ratio | U3: Average_selling_Price | V3: Unit_Profit | W3: Is_Loss
A4: Channel Partners | B4: United States of America | C4: Paseo | D4: High | E4: 914 | F4: 10 | G4: 12 | H4: 10968 | I4: 1645.2 | J4: 9322.8 | K4: 2742 | L4: 6580.8 | M4: 41651 | N4: 12 | O4: December | P4: 2014 | Q4: 0 | R4: 0.70588235 | S4: 0.29411765 | T4: 0.17647059 | U4: 10.2 | V4: 7.2 | W4: 0
A5: Channel Partners | B5: Canada | C5: Paseo | D5: High | E5: 2222 | F5: 10 | G5: 12 | H5: 26664 | I5: 3732.96 | J5: 22931.04 | K5: 6666 | L5: 16265.04 | M5: 41285 | N5: 11 | O5: November | P5: 2013 | Q5: 0 | R5: 0.70930233 | S5: 0.29069767 | T5: 0.1627907 | U5: 10.32 | V5: 7.32 | W5: 0
A6: Channel Partners | B6: United States of America | C6: Paseo | D6: High | E6: 2914 | F6: 10 | G6: 12 | H6: 34968 | I6: 4895.52 | J6: 30072.48 | K6: 8742 | L6: 21330.48 | M6: 41649 | N6: 10 | O6: October | P6: 2014 | Q6: 0 | R6: 0.70930233 | S6: 0.29069767 | T6: 0.1627907 | U6: 10.32 | V6: 7.32 | W6: 0
A7: Channel Partners | B7: France | C7: Paseo | D7: High | E7: 1393 | F7: 10 | G7: 12 | H7: 16716 | I7: 2340.24 | J7: 14375.76 | K7: 4179 | L7: 10196.76 | M7: 41649 | N7: 10 | O7: October | P7: 2014 | Q7: 0 | R7: 0.70930233 | S7: 0.29069767 | T7: 0.1627907 | U7: 10.32 | V7: 7.32 | W7: 0
A8: Channel Partners | B8: Germany | C8: Paseo | D8: High | E8: 1013 | F8: 10 | G8: 12 | H8: 12156 | I8: 1580.28 | J8: 10575.72 | K8: 3039 | L8: 7536.72 | M8: 41651 | N8: 12 | O8: December | P8: 2014 | Q8: 0 | R8: 0.71264368 | S8: 0.28735632 | T8: 0.14942529 | U8: 10.44 | V8: 7.44 | W8: 0
A9: Channel Partners | B9: Mexico | C9: Paseo | D9: High | E9: 571 | F9: 10 | G9: 12 | H9: 6852 | I9: 890.76 | J9: 5961.24 | K9: 1713 | L9: 4248.24 | M9: 41646 | N9: 7 | O9: July | P9: 2014 | Q9: 0 | R9: 0.71264368 | S9: 0.28735632 | T9: 0.14942529 | U9: 10.44 | V9: 7.44 | W9: 0
A10: Channel Partners | B10: France | C10: Paseo | D10: High | E10: 2425.5 | F10: 10 | G10: 12 | H10: 29106 | I10: 3201.66 | J10: 25904.34 | K10: 7276.5 | L10: 18627.84 | M10: 41646 | N10: 7 | O10: July | P10: 2014 | Q10: 1 | R10: 0.71910112 | S10: 0.28089888 | T10: 0.12359551 | U10: 10.68 | V10: 7.68 | W10: 0
A11: Channel Partners | B11: Canada | C11: Paseo | D11: High | E11: 4026 | F11: 10 | G11: 12 | H11: 48312 | I11: 5314.32 | J11: 42997.68 | K11: 12078 | L11: 30919.68 | M11: 41646 | N11: 7 | O11: July | P11: 2014 | Q11: 0 | R11: 0.71910112 | S11: 0.28089888 | T11: 0.12359551 | U11: 10.68 | V11: 7.68 | W11: 0
A12: Channel Partners | B12: France | C12: Paseo | D12: High | E12: 1198 | F12: 10 | G12: 12 | H12: 14376 | I12: 1581.36 | J12: 12794.64 | K12: 3594 | L12: 9200.64 | M12: 41284 | N12: 10 | O12: October | P12: 2013 | Q12: 0 | R12: 0.71910112 | S12: 0.28089888 | T12: 0.12359551 | U12: 10.68 | V12: 7.68 | W12: 0
A13: Channel Partners | B13: United States of America | C13: Paseo | D13: High | E13: 386 | F13: 10 | G13: 12 | H13: 4632 | I13: 463.2 | J13: 4168.8 | K13: 1158 | L13: 3010.8 | M13: 41284 | N13: 10 | O13: October | P13: 2013 | Q13: 0 | R13: 0.72222222 | S13: 0.27777778 | T13: 0.11111111 | U13: 10.8 | V13: 7.8 | W13: 0
A14: Channel Partners | B14: Germany | C14: Paseo | D14: Medium | E14: 1775 | F14: 10 | G14: 12 | H14: 21300 | I14: 1917 | J14: 19383 | K14: 5325 | L14: 14058 | M14: 41285 | N14: 11 | O14: November | P14: 2013 | Q14: 0 | R14: 0.72527473 | S14: 0.27472527 | T14: 0.098901099 | U14: 10.92 | V14: 7.92 | W14: 0
A15: Channel Partners | B15: Mexico | C15: Paseo | D15: Medium | E15: 367 | F15: 10 | G15: 12 | H15: 4404 | I15: 396.36 | J15: 4007.64 | K15: 1101 | L15: 2906.64 | M15: 41284 | N15: 10 | O15: October | P15: 2013 | Q15: 0 | R15: 0.72527473 | S15: 0.27472527 | T15: 0.098901099 | U15: 10.92 | V15: 7.92 | W15: 0
... A29: Channel Partners | B29: United States of America | C29: Paseo | D29: None | E29: 912 | F29: 10 | G29: 12 | H29: 10944 | I29: 0 | J29: 10944 | K29: 2736 | L29: 8208 | M29: 41285 | N29: 11 | O29: November | P29: 2013 | Q29: 0 | R29: 0.75 | S29: 0.25 | T29: 0 | U29: 12 | V29: 9 | W29: 0

Sheet Detail2
A1: Details for Sum of Profit - Segment: Enterprise
A3: Segment | B3: Country | C3: Product | D3: Discount_Band | E3: Units_Sold | F3: Manufacturing_Price | G3: Sale_Price | H3: Gross_Sales | I3: Discounts | J3: Sales | K3: COGS | L3: Profit | M3: Date | N3: Month_Number | O3: Month_Name | P3: Year | Q3: is_fractional_units | R3: Profit_Margin | S3: Cogs_Ratio | T3: Discount_Ratio | U3: Average_selling_Price | V3: Unit_Profit | W3: Is_Loss
A4: Enterprise | B4: United States of America | C4: Amarilla | D4: High | E4: 2844 | F4: 260 | G4: 125 | H4: 355500 | I4: 49770 | J4: 305730 | K4: 341280 | L4: -35550 | M4: 41644 | N4: 5 | O4: May | P4: 2014 | Q4: 0 | R4: -0.11627907 | S4: 1.1162791 | T4: 0.1627907 | U4: 107.5 | V4: -12.5 | W4: 1
A5: Enterprise | B5: Canada | C5: Amarilla | D5: High | E5: 1659 | F5: 260 | G5: 125 | H5: 207375 | I5: 26958.75 | J5: 180416.25 | K5: 199080 | L5: -18663.75 | M5: 41640 | N5: 1 | O5: January | P5: 2014 | Q5: 0 | R5: -0.10344828 | S5: 1.1034483 | T5: 0.14942529 | U5: 108.75 | V5: -11.25 | W5: 1
A6: Enterprise | B6: Mexico | C6: Amarilla | D6: High | E6: 947 | F6: 260 | G6: 125 | H6: 118375 | I6: 13021.25 | J6: 105353.75 | K6: 113640 | L6: -8286.25 | M6: 41283 | N6: 9 | O6: September | P6: 2013 | Q6: 0 | R6: -0.078651685 | S6: 1.0786517 | T6: 0.12359551 | U6: 111.25 | V6: -8.75 | W6: 1
A7: Enterprise | B7: France | C7: Amarilla | D7: High | E7: 1433 | F7: 260 | G7: 125 | H7: 179125 | I7: 19703.75 | J7: 159421.25 | K7: 171960 | L7: -12538.75 | M7: 41644 | N7: 5 | O7: May | P7: 2014 | Q7: 0 | R7: -0.078651685 | S7: 1.0786517 | T7: 0.12359551 | U7: 111.25 | V7: -8.75 | W7: 1
A8: Enterprise | B8: Germany | C8: Amarilla | D8: High | E8: 3165 | F8: 260 | G8: 125 | H8: 395625 | I8: 43518.75 | J8: 352106.25 | K8: 379800 | L8: -27693.75 | M8: 41640 | N8: 1 | O8: January | P8: 2014 | Q8: 0 | R8: -0.078651685 | S8: 1.0786517 | T8: 0.12359551 | U8: 111.25 | V8: -8.75 | W8: 1
A9: Enterprise | B9: United States of America | C9: Amarilla | D9: High | E9: 579 | F9: 260 | G9: 125 | H9: 72375 | I9: 7237.5 | J9: 65137.5 | K9: 69480 | L9: -4342.5 | M9: 41640 | N9: 1 | O9: January | P9: 2014 | Q9: 0 | R9: -0.066666667 | S9: 1.0666667 | T9: 0.11111111 | U9: 112.5 | V9: -7.5 | W9: 1
A10: Enterprise | B10: Germany | C10: Amarilla | D10: Medium | E10: 994 | F10: 260 | G10: 125 | H10: 124250 | I10: 8697.5 | J10: 115552.5 | K10: 119280 | L10: -3727.5 | M10: 41283 | N10: 9 | O10: September | P10: 2013 | Q10: 0 | R10: -0.032258065 | S10: 1.0322581 | T10: 0.075268817 | U10: 116.25 | V10: -3.75 | W10: 1
A11: Enterprise | B11: Germany | C11: Amarilla | D11: None | E11: 4219.5 | F11: 260 | G11: 125 | H11: 527437.5 | I11: 0 | J11: 527437.5 | K11: 506340 | L11: 21097.5 | M11: 41643 | N11: 4 | O11: April | P11: 2014 | Q11: 1 | R11: 0.04 | S11: 0.96 | T11: 0 | U11: 125 | V11: 5 | W11: 0
A12: Enterprise | B12: Canada | C12: Amarilla | D12: Medium | E12: 1645 | F12: 260 | G12: 125 | H12: 205625 | I12: 14393.75 | J12: 191231.25 | K12: 197400 | L12: -6168.75 | M12: 41644 | N12: 5 | O12: May | P12: 2014 | Q12: 0 | R12: -0.032258065 | S12: 1.0322581 | T12: 0.075268817 | U12: 116.25 | V12: -3.75 | W12: 1
A13: Enterprise | B13: France | C13: Amarilla | D13: Medium | E13: 1987.5 | F13: 260 | G13: 125 | H13: 248437.5 | I13: 14906.25 | J13: 233531.25 | K13: 238500 | L13: -4968.75 | M13: 41640 | N13: 1 | O13: January | P13: 2014 | Q13: 1 | R13: -0.021276596 | S13: 1.0212766 | T13: 0.063829787 | U13: 117.5 | V13: -2.5 | W13: 1
A14: Enterprise | B14: Germany | C14: Amarilla | D14: Low | E14: 2276 | F14: 260 | G14: 125 | H14: 284500 | I14: 5690 | J14: 278810 | K14: 273120 | L14: 5690 | M14: 41644 | N14: 5 | O14: May | P14: 2014 | Q14: 0 | R14: 0.020408163 | S14: 0.97959184 | T14: 0.020408163 | U14: 122.5 | V14: 2.5 | W14: 0
A15: Enterprise | B15: Germany | C15: Carretera | D15: High | E15: 1085 | F15: 3 | G15: 125 | H15: 135625 | I15: 20343.75 | J15: 115281.25 | K15: 130200 | L15: -14918.75 | M15: 41649 | N15: 10 | O15: October | P15: 2014 | Q15: 0 | R15: -0.12941176 | S15: 1.1294118 | T15: 0.17647059 | U15: 106.25 | V15: -13.75 | W15: 1
... A98: Enterprise | B98: France | C98: VTT | D98: Low | E98: 1744 | F98: 250 | G98: 125 | H98: 218000 | I98: 2180 | J98: 215820 | K98: 209280 | L98: 6540 | M98: 41650 | N98: 11 | O98: November | P98: 2014 | Q98: 0 | R98: 0.03030303 | S98: 0.96969697 | T98: 0.01010101 | U98: 123.75 | V98: 3.75 | W98: 0

Sheet Sheet7
A3: Row Labels | B3: Sum of Sales | C3: Sum of Profit | D3: Sum of Profit margin
A4: Channel Partners | B4: 1800593.6 | C4: 1316803.1 | D4: 0.73131611
A5: Enterprise | B5: 18755734 | C5: -614545.62 | D5: -0.032765746
A6: Government | B6: 52504261 | C6: 11388173 | D6: 0.21689998
A7: Midmarket | B7: 2381883.1 | C7: 660103.09 | D7: 0.27713497
A8: Small Business | B8: 42427918 | C8: 4143168.5 | D8: 0.097651939
A9: Grand Total | B9: 1.1787039e+08 | C9: 16893702 | D9: 0.14332439
A11: Row Labels | B11: Sum of Sales | C11: Sum of Profit | D11: Sum of Profit margin
A12: 2013 | B12: 26415256 | C12: 3878464.5 | D12: 0.14682669
A13: 2014 | B13: 91455135 | C13: 13015238 | D13: 0.14231282
A14: Grand Total | B14: 1.1787039e+08 | C14: 16893702 | D14: 0.14332439
A16: Sum of Sales | B16: Sum of Profit | C16: Sum of Profit margin
A17: 1.1787039e+08 | B17: 16893702 | C17: 0.14332439
A19: Row Labels | B19: Sum of Sales | C19: Sum of Profit | D19: Sum of Profit margin
A20: Amarilla | B20: 17618236 | C20: 2814104.1 | D20: 0.15972678
A21: Carretera | B21: 13815308 | C21: 1826804.9 | D21: 0.13223049
A22: Montana | B22: 15254242 | C22: 2114754.9 | D22: 0.13863389
A23: Paseo | B23: 32420624 | C23: 4797438 | D23: 0.14797488
A24: Velo | B24: 18250059 | C24: 2305992.5 | D24: 0.12635534
A25: VTT | B25: 20511921 | C25: 3034608 | D25: 0.14794363
A26: Grand Total | B26: 1.1787039e+08 | C26: 16893702 | D26: 0.14332439
A28: Row Labels | B28: Sum of Sales | C28: Sum of Profit | D28: Sum of Profit margin
A29: Canada | B29: 24887655 | C29: 3529228.9 | D29: 0.14180641
A30: France | B30: 23995612 | C30: 3781020.8 | D30: 0.15757134
A31: Germany | B31: 23409941 | C31: 3680388.8 | D31: 0.15721479
A32: Mexico | B32: 20547352 | C32: 2907523.1 | D32: 0.14150354
A33: United States of America | B33: 25029830 | C33: 2995540.7 | D33: 0.11967883
A34: Grand Total | B34: 1.1787039e+08 | C34: 16893702 | D34: 0.14332439
A36: Row Labels | B36: Sum of Units_Sold | C36: Sum of Sales | D36: Sum of Profit | E36: Sum of Profit margin
A37: High | B37: 398085.5 | C37: 37372487 | D37: 3388866.7 | E37: 0.090678117
A38: Low | B38: 254725.5 | C38: 33773819 | D38: 6188857.7 | E38: 0.18324424
A39: Medium | B39: 379698.5 | C39: 38780431 | D39: 5579522.8 | E39: 0.1438747
A40: None | B40: 86163.5 | C40: 7943654 | D40: 1736455 | E40: 0.2185965
A41: Grand Total | B41: 1118673 | C41: 1.1787039e+08 | D41: 16893702 | E41: 0.14332439
A43: Average of Is_Loss
A44: 0.083453237
B46: Average of Is_Loss
A47: High | B47: 0.13469388
A48: Low | B48: 0
A49: Medium | B49: 0.10330579
...

Sheet Financials
A1: Segment | B1: Country | C1: Product | D1: Discount_Band | E1: Units_Sold | F1: Manufacturing_Price | G1: Sale_Price | H1: Gross_Sales | I1: Discounts | J1: Sales | K1: COGS | L1: Profit | M1: Date | N1: Month_Number | O1: Month_Name | P1: Year | Q1: is_fractional_units | R1: Profit_Margin | S1: Cogs_Ratio | T1: Discount_Ratio | U1: Average_selling_Price | V1: Unit_Profit | W1: Is_Loss
A2: Government | B2: Canada | C2: Carretera | D2: None | E2: 1618.5 | F2: 3 | G2: 20 | H2: 32370 | I2: 0 | J2: 32370 | K2: 16185 | L2: 16185 | M2: 41640 | N2: 1 | O2: January | P2: 2014 | Q2: =IF(Financials[[#This Row],[ Units_Sold ]]<>INT(Financials[[#This Row],[ Units_Sold ]]),1,0) | R2: =Financials[[#This Row],[ Profit ]]/Financials[[#This Row],[ Sales ]] | S2: =Financials[[#This Row],[ COGS ]]/Financials[[#This Row],[ Sales ]] | T2: =Financials[[#This Row],[ Discounts ]]/Financials[[#This Row],[ Sales ]] | U2: =Financials[[#This Row],[ Sales ]]/Financials[[#This Row],[ Units_Sold ]] | V2: =Financials[[#This Row],[ Profit ]]/Financials[[#This Row],[ Units_Sold ]] | W2: =IF(Financials[[#This Row],[ Profit ]]<0,1,0)
A3: Government | B3: Germany | C3: Carretera | D3: None | E3: 1321 | F3: 3 | G3: 20 | H3: 26420 | I3: 0 | J3: 26420 | K3: 13210 | L3: 13210 | M3: 41640 | N3: 1 | O3: January | P3: 2014 | Q3: =IF(Financials[[#This Row],[ Units_Sold ]]<>INT(Financials[[#This Row],[ Units_Sold ]]),1,0) | R3: =Financials[[#This Row],[ Profit ]]/Financials[[#This Row],[ Sales ]] | S3: =Financials[[#This Row],[ COGS ]]/Financials[[#This Row],[ Sales ]] | T3: =Financials[[#This Row],[ Discounts ]]/Financials[[#This Row],[ Sales ]] | U3: =Financials[[#This Row],[ Sales ]]/Financials[[#This Row],[ Units_Sold ]] | V3: =Financials[[#This Row],[ Profit ]]/Financials[[#This Row],[ Units_Sold ]] | W3: =IF(Financials[[#This Row],[ Profit ]]<0,1,0)
A4: Midmarket | B4: France | C4: Carretera | D4: None | E4: 2178 | F4: 3 | G4: 15 | H4: 32670 | I4: 0 | J4: 32670 | K4: 21780 | L4: 10890 | M4: 41645 | N4: 6 | O4: June | P4: 2014 | Q4: =IF(Financials[[#This Row],[ Units_Sold ]]<>INT(Financials[[#This Row],[ Units_Sold ]]),1,0) | R4: =Financials[[#This Row],[ Profit ]]/Financials[[#This Row],[ Sales ]] | S4: =Financials[[#This Row],[ COGS ]]/Financials[[#This Row],[ Sales ]] | T4: =Financials[[#This Row],[ Discounts ]]/Financials[[#This Row],[ Sales ]] | U4: =Financials[[#This Row],[ Sales ]]/Financials[[#This Row],[ Units_Sold ]] | V4: =Financials[[#This Row],[ Profit ]]/Financials[[#This Row],[ Units_Sold ]] | W4: =IF(Financials[[#This Row],[ Profit ]]<0,1,0)
A5: Midmarket | B5: Germany | C5: Carretera | D5: None | E5: 888 | F5: 3 | G5: 15 | H5: 13320 | I5: 0 | J5: 13320 | K5: 8880 | L5: 4440 | M5: 41645 | N5: 6 | O5: June | P5: 2014 | Q5: =IF(Financials[[#This Row],[ Units_Sold ]]<>INT(Financials[[#This Row],[ Units_Sold ]]),1,0) | R5: =Financials[[#This Row],[ Profit ]]/Financials[[#This Row],[ Sales ]] | S5: =Financials[[#This Row],[ COGS ]]/Financials[[#This Row],[ Sales ]] | T5: =Financials[[#This Row],[ Discounts ]]/Financials[[#This Row],[ Sales ]] | U5: =Financials[[#This Row],[ Sales ]]/Financials[[#This Row],[ Units_Sold ]] | V5: =Financials[[#This Row],[ Profit ]]/Financials[[#This Row],[ Units_Sold ]] | W5: =IF(Financials[[#This Row],[ Profit ]]<0,1,0)
A6: Midmarket | B6: Mexico | C6: Carretera | D6: None | E6: 2470 | F6: 3 | G6: 15 | H6: 37050 | I6: 0 | J6: 37050 | K6: 24700 | L6: 12350 | M6: 41645 | N6: 6 | O6: June | P6: 2014 | Q6: =IF(Financials[[#This Row],[ Units_Sold ]]<>INT(Financials[[#This Row],[ Units_Sold ]]),1,0) | R6: =Financials[[#This Row],[ Profit ]]/Financials[[#This Row],[ Sales ]] | S6: =Financials[[#This Row],[ COGS ]]/Financials[[#This Row],[ Sales ]] | T6: =Financials[[#This Row],[ Discounts ]]/Financials[[#This Row],[ Sales ]] | U6: =Financials[[#This Row],[ Sales ]]/Financials[[#This Row],[ Units_Sold ]] | V6: =Financials[[#This Row],[ Profit ]]/Financials[[#This Row],[ Units_Sold ]] | W6: =IF(Financials[[#This Row],[ Profit ]]<0,1,0)
A7: Government | B7: Germany | C7: Carretera | D7: None | E7: 1513 | F7: 3 | G7: 350 | H7: 529550 | I7: 0 | J7: 529550 | K7: 393380 | L7: 136170 | M7: 41651 | N7: 12 | O7: December | P7: 2014 | Q7: =IF(Financials[[#This Row],[ Units_Sold ]]<>INT(Financials[[#This Row],[ Units_Sold ]]),1,0) | R7: =Financials[[#This Row],[ Profit ]]/Financials[[#This Row],[ Sales ]] | S7: =Financials[[#This Row],[ COGS ]]/Financials[[#This Row],[ Sales ]] | T7: =Financials[[#This Row],[ Discounts ]]/Financials[[#This Row],[ Sales ]] | U7: =Financials[[#This Row],[ Sales ]]/Financials[[#This Row],[ Units_Sold ]] | V7: =Financials[[#This Row],[ Profit ]]/Financials[[#This Row],[ Units_Sold ]] | W7: =IF(Financials[[#This Row],[ Profit ]]<0,1,0)
A8: Midmarket | B8: Germany | C8: Montana | D8: None | E8: 921 | F8: 5 | G8: 15 | H8: 13815 | I8: 0 | J8: 13815 | K8: 9210 | L8: 4605 | M8: 41642 | N8: 3 | O8: March | P8: 2014 | Q8: =IF(Financials[[#This Row],[ Units_Sold ]]<>INT(Financials[[#This Row],[ Units_Sold ]]),1,0) | R8: =Financials[[#This Row],[ Profit ]]/Financials[[#This Row],[ Sales ]] | S8: =Financials[[#This Row],[ COGS ]]/Financials[[#This Row],[ Sales ]] | T8: =Financials[[#This Row],[ Discounts ]]/Financials[[#This Row],[ Sales ]] | U8: =Financials[[#This Row],[ Sales ]]/Financials[[#This Row],[ Units_Sold ]] | V8: =Financials[[#This Row],[ Profit ]]/Financials[[#This Row],[ Units_Sold ]] | W8: =IF(Financials[[#This Row],[ Profit ]]<0,1,0)
A9: Channel Partners | B9: Canada | C9: Montana | D9: None | E9: 2518 | F9: 5 | G9: 12 | H9: 30216 | I9: 0 | J9: 30216 | K9: 7554 | L9: 22662 | M9: 41645 | N9: 6 | O9: June | P9: 2014 | Q9: =IF(Financials[[#This Row],[ Units_Sold ]]<>INT(Financials[[#This Row],[ Units_Sold ]]),1,0) | R9: =Financials[[#This Row],[ Profit ]]/Financials[[#This Row],[ Sales ]] | S9: =Financials[[#This Row],[ COGS ]]/Financials[[#This Row],[ Sales ]] | T9: =Financials[[#This Row],[ Discounts ]]/Financials[[#This Row],[ Sales ]] | U9: =Financials[[#This Row],[ Sales ]]/Financials[[#This Row],[ Units_Sold ]] | V9: =Financials[[#This Row],[ Profit ]]/Financials[[#This Row],[ Units_Sold ]] | W9: =IF(Financials[[#This Row],[ Profit ]]<0,1,0)
A10: Government | B10: France | C10: Montana | D10: None | E10: 1899 | F10: 5 | G10: 20 | H10: 37980 | I10: 0 | J10: 37980 | K10: 18990 | L10: 18990 | M10: 41645 | N10: 6 | O10: June | P10: 2014 | Q10: =IF(Financials[[#This Row],[ Units_Sold ]]<>INT(Financials[[#This Row],[ Units_Sold ]]),1,0) | R10: =Financials[[#This Row],[ Profit ]]/Financials[[#This Row],[ Sales ]] | S10: =Financials[[#This Row],[ COGS ]]/Financials[[#This Row],[ Sales ]] | T10: =Financials[[#This Row],[ Discounts ]]/Financials[[#This Row],[ Sales ]] | U10: =Financials[[#This Row],[ Sales ]]/Financials[[#This Row],[ Units_Sold ]] | V10: =Financials[[#This Row],[ Profit ]]/Financials[[#This Row],[ Units_Sold ]] | W10: =IF(Financials[[#This Row],[ Profit ]]<0,1,0)
A11: Channel Partners | B11: Germany | C11: Montana | D11: None | E11: 1545 | F11: 5 | G11: 12 | H11: 18540 | I11: 0 | J11: 18540 | K11: 4635 | L11: 13905 | M11: 41645 | N11: 6 | O11: June | P11: 2014 | Q11: =IF(Financials[[#This Row],[ Units_Sold ]]<>INT(Financials[[#This Row],[ Units_Sold ]]),1,0) | R11: =Financials[[#This Row],[ Profit ]]/Financials[[#This Row],[ Sales ]] | S11: =Financials[[#This Row],[ COGS ]]/Financials[[#This Row],[ Sales ]] | T11: =Financials[[#This Row],[ Discounts ]]/Financials[[#This Row],[ Sales ]] | U11: =Financials[[#This Row],[ Sales ]]/Financials[[#This Row],[ Units_Sold ]] | V11: =Financials[[#This Row],[ Profit ]]/Financials[[#This Row],[ Units_Sold ]] | W11: =IF(Financials[[#This Row],[ Profit ]]<0,1,0)
A12: Midmarket | B12: Mexico | C12: Montana | D12: None | E12: 2470 | F12: 5 | G12: 15 | H12: 37050 | I12: 0 | J12: 37050 | K12: 24700 | L12: 12350 | M12: 41645 | N12: 6 | O12: June | P12: 2014 | Q12: =IF(Financials[[#This Row],[ Units_Sold ]]<>INT(Financials[[#This Row],[ Units_Sold ]]),1,0) | R12: =Financials[[#This Row],[ Profit ]]/Financials[[#This Row],[ Sales ]] | S12: =Financials[[#This Row],[ COGS ]]/Financials[[#This Row],[ Sales ]] | T12: =Financials[[#This Row],[ Discounts ]]/Financials[[#This Row],[ Sales ]] | U12: =Financials[[#This Row],[ Sales ]]/Financials[[#This Row],[ Units_Sold ]] | V12: =Financials[[#This Row],[ Profit ]]/Financials[[#This Row],[ Units_Sold ]] | W12: =IF(Financials[[#This Row],[ Profit ]]<0,1,0)
A13: Enterprise | B13: Canada | C13: Montana | D13: None | E13: 2665.5 | F13: 5 | G13: 125 | H13: 333187.5 | I13: 0 | J13: 333187.5 | K13: 319860 | L13: 13327.5 | M13: 41646 | N13: 7 | O13: July | P13: 2014 | Q13: =IF(Financials[[#This Row],[ Units_Sold ]]<>INT(Financials[[#This Row],[ Units_Sold ]]),1,0) | R13: =Financials[[#This Row],[ Profit ]]/Financials[[#This Row],[ Sales ]] | S13: =Financials[[#This Row],[ COGS ]]/Financials[[#This Row],[ Sales ]] | T13: =Financials[[#This Row],[ Discounts ]]/Financials[[#This Row],[ Sales ]] | U13: =Financials[[#This Row],[ Sales ]]/Financials[[#This Row],[ Units_Sold ]] | V13: =Financials[[#This Row],[ Profit ]]/Financials[[#This Row],[ Units_Sold ]] | W13: =IF(Financials[[#This Row],[ Profit ]]<0,1,0)
... A696: Channel Partners | B696: United States of America | C696: VTT | D696: High | E696: 1806 | F696: 250 | G696: 12 | H696: 21672 | I696: 3250.8 | J696: 18421.2 | K696: 5418 | L696: 13003.2 | M696: 41644 | N696: 5 | O696: May | P696: 2014 | Q696: =IF(Financials[[#This Row],[ Units_Sold ]]<>INT(Financials[[#This Row],[ Units_Sold ]]),1,0) | R696: =Financials[[#This Row],[ Profit ]]/Financials[[#This Row],[ Sales ]] | S696: =Financials[[#This Row],[ COGS ]]/Financials[[#This Row],[ Sales ]] | T696: =Financials[[#This Row],[ Discounts ]]/Financials[[#This Row],[ Sales ]] | U696: =Financials[[#This Row],[ Sales ]]/Financials[[#This Row],[ Units_Sold ]] | V696: =Financials[[#This Row],[ Profit ]]/Financials[[#This Row],[ Units_Sold ]] | W696: =IF(Financials[[#This Row],[ Profit ]]<0,1,0)

Sheet Calc
A1: CALC — all dashboard numbers are live formulas on the Financials sheet (full-column references, so new rows are picked up).
A2: Segment criteria | B2: =IF(Dashboard!$H$5="All","*","*"&Dashboard!$H$5&"*")
A3: Country criteria | B3: =IF(Dashboard!$N$5="All","*","*"&Dashboard!$N$5&"*")
A4: Product criteria | B4: =IF(Dashboard!$T$5="All","*","*"&Dashboard!$T$5&"*")
A5: Year from | B5: =IF(Dashboard!$B$5="All",2000,VALUE(Dashboard!$B$5))
A6: Year to | B6: =IF(Dashboard!$B$5="All",2100,VALUE(Dashboard!$B$5))
A8: KPI block (all filters applied)
A9: Gross sales | B9: =SUMIFS(Financials!$H:$H,Financials!$A:$A,Calc!$B$2,Financials!$B:$B,Calc!$B$3,Financials!$C:$C,Calc!$B$4,Financials!$P:$P,">="&Calc!$B$5,Financials!$P:$P,"<="&Calc!$B$6)
A10: Discounts | B10: =SUMIFS(Financials!$I:$I,Financials!$A:$A,Calc!$B$2,Financials!$B:$B,Calc!$B$3,Financials!$C:$C,Calc!$B$4,Financials!$P:$P,">="&Calc!$B$5,Financials!$P:$P,"<="&Calc!$B$6)
A11: Net sales | B11: =SUMIFS(Financials!$J:$J,Financials!$A:$A,Calc!$B$2,Financials!$B:$B,Calc!$B$3,Financials!$C:$C,Calc!$B$4,Financials!$P:$P,">="&Calc!$B$5,Financials!$P:$P,"<="&Calc!$B$6)
A12: COGS | B12: =SUMIFS(Financials!$K:$K,Financials!$A:$A,Calc!$B$2,Financials!$B:$B,Calc!$B$3,Financials!$C:$C,Calc!$B$4,Financials!$P:$P,">="&Calc!$B$5,Financials!$P:$P,"<="&Calc!$B$6)
A13: Profit | B13: =SUMIFS(Financials!$L:$L,Financials!$A:$A,Calc!$B$2,Financials!$B:$B,Calc!$B$3,Financials!$C:$C,Calc!$B$4,Financials!$P:$P,">="&Calc!$B$5,Financials!$P:$P,"<="&Calc!$B$6)
A14: Units sold | B14: =SUMIFS(Financials!$E:$E,Financials!$A:$A,Calc!$B$2,Financials!$B:$B,Calc!$B$3,Financials!$C:$C,Calc!$B$4,Financials!$P:$P,">="&Calc!$B$5,Financials!$P:$P,"<="&Calc!$B$6)
A15: Orders | B15: =COUNTIFS(Financials!$A:$A,Calc!$B$2,Financials!$B:$B,Calc!$B$3,Financials!$C:$C,Calc!$B$4,Financials!$P:$P,">="&Calc!$B$5,Financials!$P:$P,"<="&Calc!$B$6)
A16: Loss-making orders | B16: =COUNTIFS(Financials!$A:$A,Calc!$B$2,Financials!$B:$B,Calc!$B$3,Financials!$C:$C,Calc!$B$4,Financials!$P:$P,">="&Calc!$B$5,Financials!$P:$P,"<="&Calc!$B$6,Financials!$L:$L,"<0")
A17: Loss $ (sum of negative profit) | B17: =SUMIFS(Financials!$L:$L,Financials!$A:$A,Calc!$B$2,Financials!$B:$B,Calc!$B$3,Financials!$C:$C,Calc!$B$4,Financials!$P:$P,">="&Calc!$B$5,Financials!$P:$P,"<="&Calc!$B$6,Financials!$L:$L,"<0")
A18: Profit margin | B18: =IFERROR(B13/B11,0)
A19: Discount rate (% of gross) | B19: =IFERROR(B10/B9,0)
A20: Loss orders % of orders | B20: =IFERROR(B16/B15,0)
A21: COGS % of net sales | B21: =IFERROR(B12/B11,0)
A23: Like-for-like Sep–Dec (filters: segment/country/product; ignores Period) | B23: 2013 | C23: 2014 | D23: % chg | E23: pp chg | F23: Favourable flag | G23: Card text
A24: Net sales | B24: =SUMIFS(Financials!$J:$J,Financials!$A:$A,Calc!$B$2,Financials!$B:$B,Calc!$B$3,Financials!$C:$C,Calc!$B$4,Financials!$P:$P,2013,Financials!$N:$N,">=9") | C24: =SUMIFS(Financials!$J:$J,Financials!$A:$A,Calc!$B$2,Financials!$B:$B,Calc!$B$3,Financials!$C:$C,Calc!$B$4,Financials!$P:$P,2014,Financials!$N:$N,">=9") | D24: =IFERROR((C24-B24)/ABS(B24),"") | F24: =IFERROR(1*SIGN(D24),0) | G24: =IF(D24="","n/a",IF(D24>=0,"▲ ","▼ ")&TEXT(D24,"+0.0%;-0.0%")&" LFL")
A25: Profit | B25: =SUMIFS(Financials!$L:$L,Financials!$A:$A,Calc!$B$2,Financials!$B:$B,Calc!$B$3,Financials!$C:$C,Calc!$B$4,Financials!$P:$P,2013,Financials!$N:$N,">=9") | C25: =SUMIFS(Financials!$L:$L,Financials!$A:$A,Calc!$B$2,Financials!$B:$B,Calc!$B$3,Financials!$C:$C,Calc!$B$4,Financials!$P:$P,2014,Financials!$N:$N,">=9") | D25: =IFERROR((C25-B25)/ABS(B25),"") | F25: =IFERROR(1*SIGN(D25),0) | G25: =IF(D25="","n/a",IF(D25>=0,"▲ ","▼ ")&TEXT(D25,"+0.0%;-0.0%")&" LFL")
A26: Gross sales | B26: =SUMIFS(Financials!$H:$H,Financials!$A:$A,Calc!$B$2,Financials!$B:$B,Calc!$B$3,Financials!$C:$C,Calc!$B$4,Financials!$P:$P,2013,Financials!$N:$N,">=9") | C26: =SUMIFS(Financials!$H:$H,Financials!$A:$A,Calc!$B$2,Financials!$B:$B,Calc!$B$3,Financials!$C:$C,Calc!$B$4,Financials!$P:$P,2014,Financials!$N:$N,">=9") | D26: =IFERROR((C26-B26)/ABS(B26),"")
A27: Discounts | B27: =SUMIFS(Financials!$I:$I,Financials!$A:$A,Calc!$B$2,Financials!$B:$B,Calc!$B$3,Financials!$C:$C,Calc!$B$4,Financials!$P:$P,2013,Financials!$N:$N,">=9") | C27: =SUMIFS(Financials!$I:$I,Financials!$A:$A,Calc!$B$2,Financials!$B:$B,Calc!$B$3,Financials!$C:$C,Calc!$B$4,Financials!$P:$P,2014,Financials!$N:$N,">=9") | D27: =IFERROR((C27-B27)/ABS(B27),"")
A28: Units sold | B28: =SUMIFS(Financials!$E:$E,Financials!$A:$A,Calc!$B$2,Financials!$B:$B,Calc!$B$3,Financials!$C:$C,Calc!$B$4,Financials!$P:$P,2013,Financials!$N:$N,">=9") | C28: =SUMIFS(Financials!$E:$E,Financials!$A:$A,Calc!$B$2,Financials!$B:$B,Calc!$B$3,Financials!$C:$C,Calc!$B$4,Financials!$P:$P,2014,Financials!$N:$N,">=9") | D28: =IFERROR((C28-B28)/ABS(B28),"") | F28: =IFERROR(1*SIGN(D28),0) | G28: =IF(D28="","n/a",IF(D28>=0,"▲ ","▼ ")&TEXT(D28,"+0.0%;-0.0%")&" LFL")
A29: Loss $ | B29: =SUMIFS(Financials!$L:$L,Financials!$A:$A,Calc!$B$2,Financials!$B:$B,Calc!$B$3,Financials!$C:$C,Calc!$B$4,Financials!$P:$P,2013,Financials!$N:$N,">=9",Financials!$L:$L,"<0") | C29: =SUMIFS(Financials!$L:$L,Financials!$A:$A,Calc!$B$2,Financials!$B:$B,Calc!$B$3,Financials!$C:$C,Calc!$B$4,Financials!$P:$P,2014,Financials!$N:$N,">=9",Financials!$L:$L,"<0") | D29: =IFERROR((ABS(C29)-ABS(B29))/ABS(B29),"") | F29: =IFERROR(-1*SIGN(D29),0) | G29: =IF(D29="","n/a",IF(D29>=0,"▲ ","▼ ")&TEXT(D29,"+0.0%;-0.0%")&" LFL")
A30: Profit margin | B30: =IFERROR(B25/B24,"") | C30: =IFERROR(C25/C24,"") | E30: =IFERROR((C30-B30)*100,"") | F30: =IFERROR(1*SIGN(E30),0) | G30: =IF(E30="","n/a",IF(E30>=0,"▲ ","▼ ")&TEXT(E30,"+0.0;-0.0")&" pp LFL")
A31: Discount rate | B31: =IFERROR(B27/B26,"") | C31: =IFERROR(C27/C26,"") | E31: =IFERROR((C31-B31)*100,"") | F31: =IFERROR(-1*SIGN(E31),0) | G31: =IF(E31="","n/a",IF(E31>=0,"▲ ","▼ ")&TEXT(E31,"+0.0;-0.0")&" pp LFL")
A34: Monthly trend (ignores Period filter)
A35: Month | B35: Year | C35: Month # | D35: Net sales | E35: Profit | F35: Profit margin
A36: Sep-13 | B36: 2013 | C36: 9 | D36: =SUMIFS(Financials!$J:$J,Financials!$A:$A,Calc!$B$2,Financials!$B:$B,Calc!$B$3,Financials!$C:$C,Calc!$B$4,Financials!$P:$P,B36,Financials!$N:$N,C36) | E36: =SUMIFS(Financials!$L:$L,Financials!$A:$A,Calc!$B$2,Financials!$B:$B,Calc!$B$3,Financials!$C:$C,Calc!$B$4,Financials!$P:$P,B36,Financials!$N:$N,C36) | F36: =IFERROR(E36/D36,NA())
A37: Oct-13 | B37: 2013 | C37: 10 | D37: =SUMIFS(Financials!$J:$J,Financials!$A:$A,Calc!$B$2,Financials!$B:$B,Calc!$B$3,Financials!$C:$C,Calc!$B$4,Financials!$P:$P,B37,Financials!$N:$N,C37) | E37: =SUMIFS(Financials!$L:$L,Financials!$A:$A,Calc!$B$2,Financials!$B:$B,Calc!$B$3,Financials!$C:$C,Calc!$B$4,Financials!$P:$P,B37,Financials!$N:$N,C37) | F37: =IFERROR(E37/D37,NA())
A38: Nov-13 | B38: 2013 | C38: 11 | D38: =SUMIFS(Financials!$J:$J,Financials!$A:$A,Calc!$B$2,Financials!$B:$B,Calc!$B$3,Financials!$C:$C,Calc!$B$4,Financials!$P:$P,B38,Financials!$N:$N,C38) | E38: =SUMIFS(Financials!$L:$L,Financials!$A:$A,Calc!$B$2,Financials!$B:$B,Calc!$B$3,Financials!$C:$C,Calc!$B$4,Financials!$P:$P,B38,Financials!$N:$N,C38) | F38: =IFERROR(E38/D38,NA())
A39: Dec-13 | B39: 2013 | C39: 12 | D39: =SUMIFS(Financials!$J:$J,Financials!$A:$A,Calc!$B$2,Financials!$B:$B,Calc!$B$3,Financials!$C:$C,Calc!$B$4,Financials!$P:$P,B39,Financials!$N:$N,C39) | E39: =SUMIFS(Financials!$L:$L,Financials!$A:$A,Calc!$B$2,Financials!$B:$B,Calc!$B$3,Financials!$C:$C,Calc!$B$4,Financials!$P:$P,B39,Financials!$N:$N,C39) | F39: =IFERROR(E39/D39,NA())
A40: Jan-14 | B40: 2014 | C40: 1 | D40: =SUMIFS(Financials!$J:$J,Financials!$A:$A,Calc!$B$2,Financials!$B:$B,Calc!$B$3,Financials!$C:$C,Calc!$B$4,Financials!$P:$P,B40,Financials!$N:$N,C40) | E40: =SUMIFS(Financials!$L:$L,Financials!$A:$A,Calc!$B$2,Financials!$B:$B,Calc!$B$3,Financials!$C:$C,Calc!$B$4,Financials!$P:$P,B40,Financials!$N:$N,C40) | F40: =IFERROR(E40/D40,NA())
A41: Feb-14 | B41: 2014 | C41: 2 | D41: =SUMIFS(Financials!$J:$J,Financials!$A:$A,Calc!$B$2,Financials!$B:$B,Calc!$B$3,Financials!$C:$C,Calc!$B$4,Financials!$P:$P,B41,Financials!$N:$N,C41) | E41: =SUMIFS(Financials!$L:$L,Financials!$A:$A,Calc!$B$2,Financials!$B:$B,Calc!$B$3,Financials!$C:$C,Calc!$B$4,Financials!$P:$P,B41,Financials!$N:$N,C41) | F41: =IFERROR(E41/D41,NA())
A42: Mar-14 | B42: 2014 | C42: 3 | D42: =SUMIFS(Financials!$J:$J,Financials!$A:$A,Calc!$B$2,Financials!$B:$B,Calc!$B$3,Financials!$C:$C,Calc!$B$4,Financials!$P:$P,B42,Financials!$N:$N,C42) | E42: =SUMIFS(Financials!$L:$L,Financials!$A:$A,Calc!$B$2,Financials!$B:$B,Calc!$B$3,Financials!$C:$C,Calc!$B$4,Financials!$P:$P,B42,Financials!$N:$N,C42) | F42: =IFERROR(E42/D42,NA())
A43: Apr-14 | B43: 2014 | C43: 4 | D43: =SUMIFS(Financials!$J:$J,Financials!$A:$A,Calc!$B$2,Financials!$B:$B,Calc!$B$3,Financials!$C:$C,Calc!$B$4,Financials!$P:$P,B43,Financials!$N:$N,C43) | E43: =SUMIFS(Financials!$L:$L,Financials!$A:$A,Calc!$B$2,Financials!$B:$B,Calc!$B$3,Financials!$C:$C,Calc!$B$4,Financials!$P:$P,B43,Financials!$N:$N,C43) | F43: =IFERROR(E43/D43,NA())
A44: May-14 | B44: 2014 | C44: 5 | D44: =SUMIFS(Financials!$J:$J,Financials!$A:$A,Calc!$B$2,Financials!$B:$B,Calc!$B$3,Financials!$C:$C,Calc!$B$4,Financials!$P:$P,B44,Financials!$N:$N,C44) | E44: =SUMIFS(Financials!$L:$L,Financials!$A:$A,Calc!$B$2,Financials!$B:$B,Calc!$B$3,Financials!$C:$C,Calc!$B$4,Financials!$P:$P,B44,Financials!$N:$N,C44) | F44: =IFERROR(E44/D44,NA())
...

Sheet Lists
A1: Period | B1: Segment | C1: Country | D1: Product | F1: Dropdown options for the Dashboard filters. Add a new value here if new segments/countries/products appear in the data.
A2: All | B2: All | C2: All | D2: All
A3: 2013 | B3: Government | C3: Canada | D3: Paseo
A4: 2014 | B4: Small Business | C4: France | D4: VTT
B5: Enterprise | C5: Germany | D5: Amarilla
B6: Midmarket | C6: Mexico | D6: Velo
B7: Channel Partners | C7: United States of America | D7: Montana
D8: Carretera

Sheet Notes
A1: Notes: definitions, data quality and validation
A3: KPI DEFINITIONS
A4: KPI | B4: Business meaning / formula | C4: Desirable direction | D4: Comparison used
A5: Net Sales | B5: Sales column = Gross Sales − Discounts. SUMIFS of Sales. | C5: Higher | D5: LFL Sep–Dec 2014 vs 2013 (% change)
A6: Profit | B6: Profit column = Sales − COGS. SUMIFS of Profit. | C6: Higher | D6: LFL % change
A7: Profit Margin | B7: Profit ÷ Net Sales (same definition as the Profit_Margin column). | C7: Higher | D7: LFL change in percentage points
A8: Discount Rate | B8: Discounts ÷ Gross Sales. Gross-sales base, so it is not distorted by the discount itself. | C8: Lower (policy lever) | D8: LFL change in percentage points
A9: Units Sold | B9: Sum of Units_Sold (36 rows have fractional units; kept as reported). | C9: Higher (alone it says nothing about profit) | D9: LFL % change
A10: Loss-Making Orders | B10: Sum of negative Profit across orders (Is_Loss = 1); count and share of orders shown beneath. | C10: Smaller loss | D10: LFL % change in loss size
A12: GRAIN AND DATA QUALITY
A13: • | B13: Grain: one row = one segment × country × product × month sales record (695 rows, no blank cells in the 16 core fields, no duplicate rows).
A14: • | B14: Date column is unreliable: day and month are swapped (the day always equals Month_Number, and the month rarely matches). Year and Month_Number are used for all time analysis; the raw column is untouched.
A15: • | B15: Period: Sep 2013 – Dec 2014. 2013 holds only Sep–Dec (175 rows) so full-year comparison is not valid. Like-for-like Sep–Dec is used instead.
A16: • | B16: Text fields carry stray spaces (e.g. " Paseo "), so filters use wildcard matching.
A17: • | B17: Manufacturing_Price × Units_Sold does not equal COGS, and Sale_Price is a segment-level price tier (Government products at $7, $20 or $350). COGS and Sales are used as reported; no costs were invented.
A18: • | B18: Currency unit is not stated; values are shown with a $ symbol.
A19: • | B19: No targets, budgets or customer-level data exist, so no target comparisons or customer metrics are shown.
A20: • | B20: Arithmetic checks on the source: Gross − Discounts = Sales (max difference 0.01) and Sales − COGS = Profit (max difference ~0) hold for all rows.
A22: WHY EACH VISUAL
A23: Trend: columns + margin line | B23: Shows whether sales growth comes with profitability; margin on a separate axis so the two scales are not confused.
A24: Waterfall | B24: The required components exist (gross sales, discounts, COGS, profit), so it explains where each sales dollar goes.
A25: Segment bars | B25: Ranks segments by profit and makes the one loss-making segment visible in red.
A26: Discount band columns | B26: Tests the link between discounting and margin.
A27: Heatmap table | B27: Separates the discount effect from segment mix; losses show as red cells.
A28: Enterprise economics table | B28: Exact values matter here, so a table is clearer than a chart.
A29: Product / country tables | B29: Margins are close, so exact values are more useful than bars.
A31: HOW TO USE / REFRESH
A32: • Use the four dropdowns on the Dashboard; every KPI, chart and table recalculates. Set all to All to reset.
A33: • Formulas read whole columns of the Financials sheet, so appended rows are included. New months need a new row in Calc (monthly block); new segments/countries/products need rows in Lists and Calc.
A34: • The dashboard uses formulas rather than PivotTables because slicers and cross-filtering cannot be created reliably outside desktop Excel. The dropdowns replace slicers.
A35: • Original sheets (Financials, Detail1, Detail2, Sheet7) are kept as received.
